Workbook

Sheet TOTAL MOD working excl biomass
A1: Details of power purchase cost per unit for MOD on the basis of rates available from bills of March 2026
B2: Name of Generating Stations | C2: Energy Charges Rate for MOD Purpose Rs./kwh | D2: FCA Rs./kwh | E2: Effective Energy Charges (Rs./kwh) | F2: Transmission Losses beyond MP periphery (%) | G2: Variable cost incl. losses | H2: Cess on Intrastate sales | I2: ED & Cess on Auxiliary Consumption | J2: Trading Margin | K2: Transmission charges | L2: FGD / Change in Law | M2: Normative fixed cost for URS | N2: Incentive p.u. | O2: Effective rate in Rs./kwh
G4: (Rs. per kwh)
A5: A | B5: B | C5: C | D5: D | E5: E=C+D | F5: F | G5: G=E/((100%-F)) | H5: H | I5: I | J5: J | K5: K | L5: L | M5: M | N5: N | O5: O=sum(G:N)
A6: 1 | B6: Arya Energy Limited (Biomass) | C6: 4.38 | E6: =C6+D6 -> 4.38 | G6: =E6/((100%-F6)) -> 4.38 | I6: =VLOOKUP(B6,'fixed cost'!$B$4:$R$116,17,0) -> 0 | O6: =SUM(G6:N6) -> 4.38 | P6: 4.38 | Q6: =C6-P6 -> 0 | R6: =Q6/P6 -> 0
A7: =A6+1 -> 2 | B7: ATPS (210MW) Chachai | C7: 1.829 | D7: 0 | E7: =C7+D7 -> 1.829 | G7: =E7/((100%-F7)) -> 1.829 | I7: =VLOOKUP(B7,'fixed cost'!$B$4:$R$116,17,0) -> 0 | O7: =SUM(G7:N7) -> 1.829 | P7: 1.913 | Q7: =C7-P7 -> -0.084 | R7: =Q7/P7 -> -0.043910089
A8: 2 | B8: ATPS (210MW) Chachai | C8: =C7 -> 1.829 | E8: =C8+D8 -> 1.829 | G8: =E8/((100%-F8)) -> 1.829 | I8: =VLOOKUP(B8,'fixed cost'!$B$4:$R$116,17,0) -> 0 | N8: 0.55 | O8: =SUM(G8:N8) -> 2.379 | P8: 1.913 | Q8: =C8-P8 -> -0.084 | R8: =Q8/P8 -> -0.043910089
A9: 2 | B9: ATPS (210MW) Chachai | C9: =C8 -> 1.829 | E9: =C9+D9 -> 1.829 | G9: =E9/((100%-F9)) -> 1.829 | I9: =VLOOKUP(B9,'fixed cost'!$B$4:$R$116,17,0) -> 0 | N9: 0.75 | O9: =SUM(G9:N9) -> 2.579 | P9: 1.913 | Q9: =C9-P9 -> -0.084 | R9: =Q9/P9 -> -0.043910089
A10: 3 | B10: Bansagar-I HPS | C10: 0.602 | E10: =C10+D10 -> 0.602 | G10: =E10/((100%-F10)) -> 0.602 | I10: =VLOOKUP(B10,'fixed cost'!$B$4:$R$116,17,0) -> 0 | O10: =SUM(G10:N10) -> 0.602 | P10: 0.602 | Q10: =C10-P10 -> 0 | R10: =Q10/P10 -> 0
A11: =+A10+1 -> 4 | B11: Bansagar-II HPS | C11: 0.457 | E11: =C11+D11 -> 0.457 | G11: =E11/((100%-F11)) -> 0.457 | I11: =VLOOKUP(B11,'fixed cost'!$B$4:$R$116,17,0) -> 0 | O11: =SUM(G11:N11) -> 0.457 | P11: 0.457 | Q11: =C11-P11 -> 0 | R11: =Q11/P11 -> 0
A12: =+A11+1 -> 5 | B12: Bansagar-III HPS | C12: 0.722 | E12: =C12+D12 -> 0.722 | G12: =E12/((100%-F12)) -> 0.722 | I12: =VLOOKUP(B12,'fixed cost'!$B$4:$R$116,17,0) -> 0 | O12: =SUM(G12:N12) -> 0.722 | P12: 0.722 | Q12: =C12-P12 -> 0 | R12: =Q12/P12 -> 0
A13: =+A12+1 -> 6 | B13: Bargi HPS | C13: 0.19 | E13: =C13+D13 -> 0.19 | G13: =E13/((100%-F13)) -> 0.19 | I13: =VLOOKUP(B13,'fixed cost'!$B$4:$R$116,17,0) -> 0 | O13: =SUM(G13:N13) -> 0.19 | P13: 0.19 | Q13: =C13-P13 -> 0 | R13: =Q13/P13 -> 0
A14: =+A13+1 -> 7 | B14: Birsinghpur HPS | C14: 0.589 | E14: =C14+D14 -> 0.589 | G14: =E14/((100%-F14)) -> 0.589 | I14: =VLOOKUP(B14,'fixed cost'!$B$4:$R$116,17,0) -> 0 | O14: =SUM(G14:N14) -> 0.589 | P14: 0.589 | Q14: =C14-P14 -> 0 | R14: =Q14/P14 -> 0
A15: 8 | B15: BLA | C15: 3.752 | E15: =C15+D15 -> 3.752 | G15: =E15/((100%-F15)) -> 3.752 | H15: 0.15 | I15: =VLOOKUP(B15,'fixed cost'!$B$4:$R$116,17,0) -> 0.08001 | O15: =SUM(G15:N15) -> 3.98201 | P15: 3.761 | Q15: =C15-P15 -> -0.009 | R15: =Q15/P15 -> -0.0023929806
A16: 9 | B16: BLA II | C16: 4.037 | E16: =C16+D16 -> 4.037 | G16: =E16/((100%-F16)) -> 4.037 | H16: 0.15 | I16: =VLOOKUP(B16,'fixed cost'!$B$4:$R$116,17,0) -> 0.08001 | O16: =SUM(G16:N16) -> 4.26701 | P16: 4.037 | Q16: =C16-P16 -> 0 | R16: =Q16/P16 -> 0
A17: 10 | B17: DVC (CTPS) (STOA LOI) | C17: 2.745 | E17: =C17+D17 -> 2.745 | F17: 0.0442 | G17: =E17/((100%-F17)) -> 2.8719397 | I17: =VLOOKUP(B17,'fixed cost'!$B$4:$R$116,17,0) -> 0 | K17: 0.024 | O17: =SUM(G17:N17) -> 2.8959397 | P17: 2.745 | Q17: =C17-P17 -> 0 | R17: =Q17/P17 -> 0
A18: 11 | B18: DVC (DTPS) (STOA LOI) | C18: 3.085 | D18: 0.165 | E18: =C18+D18 -> 3.25 | F18: =F17 -> 0.0442 | G18: =E18/((100%-F18)) -> 3.4002929 | I18: =VLOOKUP(B18,'fixed cost'!$B$4:$R$116,17,0) -> 0 | K18: 0 | L18: 0.07 | O18: =SUM(G18:N18) -> 3.4702929 | P18: 3.124 | Q18: =C18-P18 -> -0.039 | R18: =Q18/P18 -> -0.012483995
A19: 12 | B19: Mahan Energen Ltd. (5%) | C19: 2.488 | D19: -0.03 | E19: =C19+D19 -> 2.458 | F19: =F18 -> 0.0442 | G19: =E19/((100%-F19)) -> 2.5716677 | H19: 0.15 | I19: =VLOOKUP(B19,'fixed cost'!$B$4:$R$116,17,0) -> 0 | O19: =SUM(G19:N19) -> 2.7216677 | P19: 2.488 | Q19: =C19-P19 -> 0 | R19: =Q19/P19 -> 0
A20: 13 | B20: Gadarwara | C20: 3.119 | D20: 0.032 | E20: =C20+D20 -> 3.151 | F20: =F19 -> 0.0442 | G20: =E20/((100%-F20)) -> 3.2967148 | H20: 0.15 | I20: =VLOOKUP(B20,'fixed cost'!$B$4:$R$116,17,0) -> 0.058995 | L20: 0.65 | O20: =SUM(G20:N20) -> 4.1557098 | P20: 3.137 | Q20: =C20-P20 -> -0.018 | R20: =Q20/P20 -> -0.0057379662
A21: =A20+1 -> 14 | B21: Gadarwara | C21: =C20 -> 3.119 | D21: =D20 -> 0.032 | E21: =C21+D21 -> 3.151 | F21: =F20 -> 0.0442 | G21: =E21/((100%-F21)) -> 3.2967148 | H21: =H20 -> 0.15 | I21: =VLOOKUP(B21,'fixed cost'!$B$4:$R$116,17,0) -> 0.058995 | L21: =L20 -> 0.65 | M21: =VLOOKUP(B21,'fixed cost'!$B$4:$H$116,7,0) -> 2.0601461 | O21: =SUM(G21:N21) -> 6.2158559 | P21: 3.137 | Q21: =C21-P21 -> -0.018 | R21: =Q21/P21 -> -0.0057379662
A22: =A21+1 -> 15 | B22: GANDHAR (APM) | C22: 2.098 | E22: =C22+D22 -> 2.098 | F22: =F21 -> 0.0442 | G22: =E22/((100%-F22)) -> 2.1950199 | I22: =VLOOKUP(B22,'fixed cost'!$B$4:$R$116,17,0) -> 0 | O22: =SUM(G22:N22) -> 2.1950199 | P22: 2.098 | Q22: =C22-P22 -> 0 | R22: =Q22/P22 -> 0
A23: =A22+1 -> 16 | B23: GANDHAR (APM) | C23: =C22 -> 2.098 | D23: =D22 -> 0 | E23: =C23+D23 -> 2.098 | F23: =F22 -> 0.0442 | G23: =E23/((100%-F23)) -> 2.1950199 | I23: =VLOOKUP(B23,'fixed cost'!$B$4:$R$116,17,0) -> 0 | M23: =VLOOKUP(B23,'fixed cost'!$B$4:$H$116,7,0) -> 1.0465902 | O23: =SUM(G23:N23) -> 3.2416101 | P23: 2.098 | Q23: =C23-P23 -> 0 | R23: =Q23/P23 -> 0
A24: =A23+1 -> 17 | B24: GANDHAR (CLNG) | C24: 8.915 | E24: =C24+D24 -> 8.915 | F24: =F23 -> 0.0442 | G24: =E24/((100%-F24)) -> 9.3272651 | I24: =VLOOKUP(B24,'fixed cost'!$B$4:$R$116,17,0) -> 0 | O24: =SUM(G24:N24) -> 9.3272651 | P24: 8.915 | Q24: =C24-P24 -> 0 | R24: =Q24/P24 -> 0
A25: =A24+1 -> 18 | B25: GANDHAR (CLNG) | C25: =C24 -> 8.915 | D25: =D24 -> 0 | E25: =C25+D25 -> 8.915 | F25: =F24 -> 0.0442 | G25: =E25/((100%-F25)) -> 9.3272651 | I25: =VLOOKUP(B25,'fixed cost'!$B$4:$R$116,17,0) -> 0 | M25: =VLOOKUP(B25,'fixed cost'!$B$4:$H$116,7,0) -> 1.0465902 | O25: =SUM(G25:N25) -> 10.373855 | P25: 8.915 | Q25: =C25-P25 -> 0 | R25: =Q25/P25 -> 0
A26: =A25+1 -> 19 | B26: GANDHAR (LNG) | C26: 9.693 | D26: 3.353 | E26: =C26+D26 -> 13.046 | F26: =F25 -> 0.0442 | G26: =E26/((100%-F26)) -> 13.649299 | I26: =VLOOKUP(B26,'fixed cost'!$B$4:$R$116,17,0) -> 0 | O26: =SUM(G26:N26) -> 13.649299 | P26: 9.654 | Q26: =C26-P26 -> 0.039 | R26: =Q26/P26 -> 0.0040397763
A27: =A26+1 -> 20 | B27: GANDHAR (LNG) | C27: =C26 -> 9.693 | D27: =D26 -> 3.353 | E27: =C27+D27 -> 13.046 | F27: =F26 -> 0.0442 | G27: =E27/((100%-F27)) -> 13.649299 | I27: =VLOOKUP(B27,'fixed cost'!$B$4:$R$116,17,0) -> 0 | M27: =VLOOKUP(B27,'fixed cost'!$B$4:$H$116,7,0) -> 1.0465902 | O27: =SUM(G27:N27) -> 14.695889 | P27: 9.654 | Q27: =C27-P27 -> 0.039 | R27: =Q27/P27 -> 0.0040397763
A28: =A27+1 -> 21 | B28: GANDHAR (NAPM) | C28: 29.718 | E28: =C28+D28 -> 29.718 | F28: =F27 -> 0.0442 | G28: =E28/((100%-F28)) -> 31.092279 | I28: =VLOOKUP(B28,'fixed cost'!$B$4:$R$116,17,0) -> 0 | O28: =SUM(G28:N28) -> 31.092279 | P28: 29.718 | Q28: =C28-P28 -> 0 | R28: =Q28/P28 -> 0
A29: =A28+1 -> 22 | B29: GANDHAR (NAPM) | C29: =C28 -> 29.718 | D29: =D28 -> 0 | E29: =C29+D29 -> 29.718 | F29: =F28 -> 0.0442 | G29: =E29/((100%-F29)) -> 31.092279 | I29: =VLOOKUP(B29,'fixed cost'!$B$4:$R$116,17,0) -> 0 | M29: =VLOOKUP(B29,'fixed cost'!$B$4:$H$116,7,0) -> 1.0465902 | O29: =SUM(G29:N29) -> 32.138869 | P29: 29.718 | Q29: =C29-P29 -> 0 | R29: =Q29/P29 -> 0
A30: =A29+1 -> 23 | B30: Gandhi Sagar HPS | C30: 0.238 | E30: =C30+D30 -> 0.238 | G30: =E30/((100%-F30)) -> 0.238 | I30: =VLOOKUP(B30,'fixed cost'!$B$4:$R$116,17,0) -> 0 | O30: =SUM(G30:N30) -> 0.238 | P30: 0.238 | Q30: =C30-P30 -> 0 | R30: =Q30/P30 -> 0
A31: =A30+1 -> 24 | B31: ISP & OSP (25:11) | C31: =((1.856*25)+(2.326*11))/(25+11) -> 1.9996111 | E31: =C31+D31 -> 1.9996111 | G31: =E31/((100%-F31)) -> 1.9996111 | H31: 0.15 | I31: ='fixed cost'!R57 -> 0.00882 | O31: =SUM(G31:N31) -> 2.1584311 | P31: 1.9996111 | Q31: =C31-P31 -> 0 | R31: =Q31/P31 -> 0
A32: =A31+1 -> 25 | B32: Jawahar Sagar (Inter state project) | C32: 1.51 | E32: =C32+D32 -> 1.51 | G32: =E32/((100%-F32)) -> 1.51 | I32: =VLOOKUP(B32,'fixed cost'!$B$4:$R$116,17,0) -> 0 | O32: =SUM(G32:N32) -> 1.51 | P32: 1.51 | Q32: =C32-P32 -> 0 | R32: =Q32/P32 -> 0
A33: =A32+1 -> 26 | B33: Jhabua Power | C33: 2.606 | D33: -0.0099 | E33: =C33+D33 -> 2.5961 | F33: =F29 -> 0.0442 | G33: =E33/((100%-F33)) -> 2.716154 | H33: 0.15 | O33: =SUM(G33:N33) -> 2.866154 | P33: 2.599 | Q33: =C33-P33 -> 0.007 | R33: =Q33/P33 -> 0.0026933436
A34: =A33+1 -> 27 | B34: Jhinna HPS | C34: 0.608 | E34: =C34+D34 -> 0.608 | G34: =E34/((100%-F34)) -> 0.608 | I34: =VLOOKUP(B34,'fixed cost'!$B$4:$R$116,17,0) -> 0 | O34: =SUM(G34:N34) -> 0.608 | P34: 0.608 | Q34: =C34-P34 -> 0 | R34: =Q34/P34 -> 0
A35: =A34+1 -> 28 | B35: JP Bina | C35: 3.376 | E35: =C35+D35 -> 3.376 | G35: =E35/((100%-F35)) -> 3.376 | H35: 0.15 | I35: =VLOOKUP(B35,'fixed cost'!$B$4:$R$116,17,0) -> 0.06477 | O35: =SUM(G35:N35) -> 3.59077 | P35: 3.376 | Q35: =C35-P35 -> 0 | R35: =Q35/P35 -> 0
A36: =A35+1 -> 29 | B36: JP Nigrie | C36: 0.705 | E36: =C36+D36 -> 0.705 | F36: =F33 -> 0.0442 | G36: =E36/((100%-F36)) -> 0.73760201 | H36: 0.15 | I36: =VLOOKUP(B36,'fixed cost'!$B$4:$R$116,17,0) -> 0.040005 | O36: =SUM(G36:N36) -> 0.92760701 | P36: 0.68 | Q36: =C36-P36 -> 0.025 | R36: =Q36/P36 -> 0.036764706
A37: =A36+1 -> 30 | B37: KAHALGAON-II | C37: 2.702 | D37: 0.05799 | E37: =C37+D37 -> 2.75999 | F37: =F36 -> 0.0442 | G37: =E37/((100%-F37)) -> 2.8876229 | I37: =VLOOKUP(B37,'fixed cost'!$B$4:$R$116,17,0) -> 0 | O37: =SUM(G37:N37) -> 2.8876229 | P37: 2.702 | Q37: =C37-P37 -> 0 | R37: =Q37/P37 -> 0
A38: =A37+1 -> 31 | B38: KAHALGAON-II | C38: =C37 -> 2.702 | D38: =D37 -> 0.05799 | E38: =C38+D38 -> 2.75999 | F38: =F37 -> 0.0442 | G38: =E38/((100%-F38)) -> 2.8876229 | I38: =VLOOKUP(B38,'fixed cost'!$B$4:$R$116,17,0) -> 0 | M38: =VLOOKUP(B38,'fixed cost'!$B$4:$H$116,7,0) -> 0.92016616 | O38: =SUM(G38:N38) -> 3.8077891 | P38: 2.702 | Q38: =C38-P38 -> 0 | R38: =Q38/P38 -> 0
A39: =A38+1 -> 32 | B39: KAHALGAON-II | C39: =C38 -> 2.702 | D39: =D38 -> 0.05799 | E39: =C39+D39 -> 2.75999 | F39: =F38 -> 0.0442 | G39: =E39/((100%-F39)) -> 2.8876229 | I39: =VLOOKUP(B39,'fixed cost'!$B$4:$R$116,17,0) -> 0 | N39: 0.55 | O39: =SUM(G39:N39) -> 3.4376229 | P39: 2.702 | Q39: =C39-P39 -> 0 | R39: =Q39/P39 -> 0
A40: =A39+1 -> 33 | B40: KAHALGAON-II | C40: =C39 -> 2.702 | D40: =D39 -> 0.05799 | E40: =C40+D40 -> 2.75999 | F40: =F39 -> 0.0442 | G40: =E40/((100%-F40)) -> 2.8876229 | I40: =VLOOKUP(B40,'fixed cost'!$B$4:$R$116,17,0) -> 0 | N40: 0.75 | O40: =SUM(G40:N40) -> 3.6376229 | P40: 2.702 | Q40: =C40-P40 -> 0 | R40: =Q40/P40 -> 0
A41: =A38+1 -> 32 | B41: KAWAS (APM) | C41: 1.597 | E41: =C41+D41 -> 1.597 | F41: =F38 -> 0.0442 | G41: =E41/((100%-F41)) -> 1.6708516 | I41: =VLOOKUP(B41,'fixed cost'!$B$4:$R$116,17,0) -> 0 | O41: =SUM(G41:N41) -> 1.6708516 | P41: 1.597 | Q41: =C41-P41 -> 0 | R41: =Q41/P41 -> 0
...

Sheet URS 4
A1: Details of URS power purchase cost per unit for MOD for the month of March 2026
A2: Sr. No. | B2: Name of Generating Stations | C2: Energy Charges Rate for MOD Purpose Rs./kwh | D2: FCA/ MOPA in Rs./kwh | E2: Effective Energy Charges in (Rs./kwh) | F2: Transmission Losses beyond MP Periphery | G2: Variable cost incl. losses | H2: Cess on Intrastate sales | I2: ED & Cess on Auxiliary Consumption | J2: FGD / Change in Law | K2: Transmission charges | L2: Normative fixed cost for URS | M2: Variable rate at MP periphery in Rs./kwh
G4: (Rs. per kwh)
A5: A | B5: B | C5: C | D5: D | E5: E=C+D | F5: F | G5: G=E/((100%-F)) | H5: H | I5: I | J5: J | K5: K | L5: L | M5: M=sum(G:L)
A6: 1 | B6: KAWAS (NAPM) | C6: 35.627 | D6: 0 | E6: =C6+D6 -> 35.627 | F6: 0.0442 | G6: =E6/((100%-F6)) -> 37.274534 | I6: 0 | L6: 0.85915096 | M6: =SUM(G6:L6) -> 38.133685 | N6: 5.5743143 | O6: =M6-N6 -> 32.559371
A7: =+A6+1 -> 2 | B7: GANDHAR (NAPM) | C7: 29.718 | D7: 0 | E7: =C7+D7 -> 29.718 | F7: 0.0442 | G7: =E7/((100%-F7)) -> 31.092279 | I7: 0 | L7: 1.0465902 | M7: =SUM(G7:L7) -> 32.138869 | N7: 3.2347421 | O7: =M7-N7 -> 28.904127
A8: =+A7+1 -> 3 | B8: KAWAS (Liquid) | C8: 24.043 | D8: 0 | E8: =C8+D8 -> 24.043 | F8: 0.0442 | G8: =E8/((100%-F8)) -> 25.154844 | I8: 0 | L8: 0.85915096 | M8: =SUM(G8:L8) -> 26.013995 | N8: 10.344671 | O8: =M8-N8 -> 15.669324
A9: =+A8+1 -> 4 | B9: Dadri Liquid (NR) | C9: 23.874 | D9: 0 | E9: =C9+D9 -> 23.874 | F9: 0.0442 | G9: =E9/((100%-F9)) -> 24.978029 | I9: 0 | L9: 0.52960707 | M9: =SUM(G9:L9) -> 25.507636 | N9: 14.612506 | O9: =M9-N9 -> 10.89513
A10: =+A9+1 -> 5 | B10: Auraiya Liquid (NR) | C10: 18.689 | E10: =C10+D10 -> 18.689 | F10: 0.0442 | G10: =E10/((100%-F10)) -> 19.553254 | I10: 0 | L10: 0.635 | M10: =SUM(G10:L10) -> 20.188254 | N10: 32.041584 | O10: =M10-N10 -> -11.85333
A11: =+A10+1 -> 6 | B11: Anta Liquid (NR) | C11: 17.498 | E11: =C11+D11 -> 17.498 | F11: 0.0442 | G11: =E11/((100%-F11)) -> 18.307177 | I11: 0 | L11: 0.709 | M11: =SUM(G11:L11) -> 19.016177 | N11: 3.798754 | O11: =M11-N11 -> 15.217423
A12: =+A11+1 -> 7 | B12: GANDHAR (LNG) | C12: 9.693 | D12: 3.353 | E12: =C12+D12 -> 13.046 | F12: 0.0442 | G12: =E12/((100%-F12)) -> 13.649299 | I12: 0 | L12: 1.0465902 | M12: =SUM(G12:L12) -> 14.695889 | N12: 2.5247747 | O12: =M12-N12 -> 12.171115
A13: =+A12+1 -> 8 | B13: Auraiya CLNG (NR) | C13: 12.268 | E13: =C13+D13 -> 12.268 | F13: 0.0442 | G13: =E13/((100%-F13)) -> 12.835321 | I13: 0 | L13: 0.635 | M13: =SUM(G13:L13) -> 13.470321 | N13: 10.197908 | O13: =M13-N13 -> 3.2724135
A14: =+A13+1 -> 9 | B14: Dadri Comm LNG (NR) | C14: 11.683 | D14: 0 | E14: =C14+D14 -> 11.683 | F14: 0.0442 | G14: =E14/((100%-F14)) -> 12.223268 | I14: 0 | L14: 0.52960707 | M14: =SUM(G14:L14) -> 12.752876 | N14: 10.848721 | O14: =M14-N14 -> 1.9041543
A15: =+A14+1 -> 10 | B15: Auraiya LNG (NR) | C15: 11.402 | E15: =C15+D15 -> 11.402 | F15: 0.0442 | G15: =E15/((100%-F15)) -> 11.929274 | I15: 0 | L15: 0.635 | M15: =SUM(G15:L15) -> 12.564274 | N15: 25.935288 | O15: =M15-N15 -> -13.371014
A16: =+A15+1 -> 11 | B16: Anta LNG (NR) | C16: 11.266 | E16: =C16+D16 -> 11.266 | F16: 0.0442 | G16: =E16/((100%-F16)) -> 11.786985 | I16: 0 | L16: 0.709 | M16: =SUM(G16:L16) -> 12.495985 | N16: 38.017057 | O16: =M16-N16 -> -25.521072
A17: =+A16+1 -> 12 | B17: Dadri LNG (NR) | C17: 10.859 | D17: 0 | E17: =C17+D17 -> 10.859 | F17: 0.0442 | G17: =E17/((100%-F17)) -> 11.361163 | I17: 0 | L17: 0.52960707 | M17: =SUM(G17:L17) -> 11.89077 | N17: 5.7807333 | O17: =M17-N17 -> 6.1100372
A18: =+A17+1 -> 13 | B18: KAWAS (LNG) | C18: 9.578 | D18: 0 | E18: =C18+D18 -> 9.578 | F18: 0.0442 | G18: =E18/((100%-F18)) -> 10.020925 | I18: 0 | L18: 0.85915096 | M18: =SUM(G18:L18) -> 10.880076 | N18: 2.2158952 | O18: =M18-N18 -> 8.6641806
A19: =+A18+1 -> 14 | B19: GANDHAR (CLNG) | C19: 8.915 | D19: 0 | E19: =C19+D19 -> 8.915 | F19: 0.0442 | G19: =E19/((100%-F19)) -> 9.3272651 | I19: 0 | L19: 1.0465902 | M19: =SUM(G19:L19) -> 10.373855 | N19: 2.5422867 | O19: =M19-N19 -> 7.8315687
A20: =+A19+1 -> 15 | B20: Anta CLNG (NR) | C20: 9.189 | E20: =C20+D20 -> 9.189 | F20: 0.0442 | G20: =E20/((100%-F20)) -> 9.613936 | I20: 0 | L20: 0.709 | M20: =SUM(G20:L20) -> 10.322936 | N20: 3.7064832 | O20: =M20-N20 -> 6.6164528
A21: =+A20+1 -> 16 | B21: KAWAS (CLNG) | C21: 8.954 | E21: =C21+D21 -> 8.954 | F21: 0.0442 | G21: =E21/((100%-F21)) -> 9.3680686 | I21: 0 | L21: 0.85915096 | M21: =SUM(G21:L21) -> 10.22722 | N21: 4.9576545 | O21: =M21-N21 -> 5.2695651
A22: =+A21+1 -> 17 | B22: Ghatampur Thermal Power Station (NUPPL) | C22: 3.412 | D22: 0 | E22: =C22+D22 -> 3.412 | F22: 0.0442 | G22: =E22/((100%-F22)) -> 3.5697845 | J22: 0 | L22: 3.3963081 | M22: =SUM(G22:L22) -> 6.9660926 | N22: 4.8270345 | O22: =M22-N22 -> 2.1390581
A23: =+A22+1 -> 18 | B23: Solapur I | C23: 3.94 | D23: 0.022 | E23: =C23+D23 -> 3.962 | F23: 0.0442 | G23: =E23/((100%-F23)) -> 4.1452187 | I23: 0 | J23: 0.096 | L23: 1.9962859 | M23: =SUM(G23:L23) -> 6.2375045 | N23: 1.7179762 | O23: =M23-N23 -> 4.5195283
A24: =+A23+1 -> 19 | B24: Gadarwara | C24: 3.119 | D24: 0.032 | E24: =C24+D24 -> 3.151 | F24: 0.0442 | G24: =E24/((100%-F24)) -> 3.2967148 | H24: 0.15 | I24: 0.058995 | J24: 0.65 | L24: 2.0601461 | M24: =SUM(G24:L24) -> 6.2158559 | N24: 2.6636987 | O24: =M24-N24 -> 3.5521572
A25: =+A24+1 -> 20 | B25: Indira Gandhi STPS (Jhajjar) (NR) | C25: 4.158 | D25: 0.031 | E25: =C25+D25 -> 4.189 | F25: 0.0442 | G25: =E25/((100%-F25)) -> 4.382716 | I25: 0 | L25: 1.56 | M25: =SUM(G25:L25) -> 5.942716 | N25: 2.3967263 | O25: =M25-N25 -> 3.5459897
A26: =+A25+1 -> 21 | B26: Khargone | C26: 3.201 | D26: -0.023 | E26: =C26+D26 -> 3.178 | F26: 0.0442 | G26: =E26/((100%-F26)) -> 3.3249634 | H26: 0.15 | I26: 0.052785 | J26: 0.062 | L26: 2.0731461 | M26: =SUM(G26:L26) -> 5.6628945 | N26: 6.245265 | O26: =M26-N26 -> -0.58237053
A27: =+A26+1 -> 22 | B27: Unchahar II (NR) | C27: 3.386 | D27: 0.19299 | E27: =C27+D27 -> 3.57899 | F27: 0.0442 | G27: =E27/((100%-F27)) -> 3.7444968 | I27: 0 | J27: 0.7 | L27: 1.1206832 | M27: =SUM(G27:L27) -> 5.56518 | N27: 3.4828769 | O27: =M27-N27 -> 2.0823031
A28: =+A27+1 -> 23 | B28: Meja (NR) | C28: 2.966 | D28: 0 | E28: =C28+D28 -> 2.966 | F28: 0.0442 | G28: =E28/((100%-F28)) -> 3.1031597 | I28: 0 | L28: 2.2494753 | M28: =SUM(G28:L28) -> 5.3526349 | N28: 3.5840453 | O28: =M28-N28 -> 1.7685896
A29: =+A28+1 -> 24 | B29: Unchahar IV (NR) | C29: 3.173 | D29: 0.158 | E29: =C29+D29 -> 3.331 | F29: 0.0442 | G29: =E29/((100%-F29)) -> 3.4850387 | I29: 0 | J29: 0.066 | L29: 1.6577601 | M29: =SUM(G29:L29) -> 5.2087988 | N29: 3.3512485 | O29: =M29-N29 -> 1.8575503
A30: =+A29+1 -> 25 | B30: Tanda II | C30: 2.851 | D30: 0.063 | E30: =C30+D30 -> 2.914 | F30: 0.0442 | G30: =E30/((100%-F30)) -> 3.048755 | I30: 0 | K30: 0.23259 | L30: 1.7669774 | M30: =SUM(G30:L30) -> 5.0483224 | N30: 4.0635438 | O30: =M30-N30 -> 0.98477853
A31: =+A30+1 -> 26 | B31: Mauda-I | C31: 3.226 | D31: -0.036 | E31: =C31+D31 -> 3.19 | F31: 0.0442 | G31: =E31/((100%-F31)) -> 3.3375183 | I31: 0 | L31: 1.6931572 | M31: =SUM(G31:L31) -> 5.0306755 | N31: 3.88687 | O31: =M31-N31 -> 1.1438055
A32: =+A31+1 -> 27 | B32: Mauda-II | C32: 3.152 | D32: -0.0349 | E32: =C32+D32 -> 3.1171 | F32: 0.0442 | G32: =E32/((100%-F32)) -> 3.2612471 | I32: 0 | J32: 0.071 | L32: 1.5812064 | M32: =SUM(G32:L32) -> 4.9134535 | N32: 2.8001556 | O32: =M32-N32 -> 2.1132979
A33: =+A32+1 -> 28 | B33: Unchahar III (NR) | C33: 3.339 | D33: 0.119 | E33: =C33+D33 -> 3.458 | F33: 0.0442 | G33: =E33/((100%-F33)) -> 3.6179117 | I33: 0 | J33: 0.071 | L33: 1.2090519 | M33: =SUM(G33:L33) -> 4.8979636 | N33: 10.381507 | O33: =M33-N33 -> -5.4835437
A34: =+A33+1 -> 29 | B34: National Capital Thermal Power Station Dadri II (NR) | C34: 3.72 | D34: 0.165 | E34: =C34+D34 -> 3.885 | F34: 0.0442 | G34: =E34/((100%-F34)) -> 4.0646579 | I34: 0 | J34: 0.06 | L34: 0.65153793 | M34: =SUM(G34:L34) -> 4.7761958 | N34: 12.270327 | O34: =M34-N34 -> -7.4941308
A35: =+A34+1 -> 30 | B35: Unchahar I (NR) | C35: 3.35 | D35: 0.115 | E35: =C35+D35 -> 3.465 | F35: 0.0442 | G35: =E35/((100%-F35)) -> 3.6252354 | I35: 0 | J35: 0.074 | L35: 1.0459098 | M35: =SUM(G35:L35) -> 4.7451452 | N35: 18.958896 | O35: =M35-N35 -> -14.213751
A36: =+A35+1 -> 31 | B36: VSTPS-IV | C36: 1.984 | D36: -0.001 | E36: =C36+D36 -> 1.983 | F36: 0.0442 | G36: =E36/((100%-F36)) -> 2.0747018 | H36: 0.15 | I36: 0.058719 | J36: 0.036 | L36: 1.6494464 | M36: =SUM(G36:L36) -> 3.9688673 | N36: 2.8095932 | O36: =M36-N36 -> 1.159274
A37: =+A36+1 -> 32 | B37: VSTPS-V | C37: 1.862 | D37: -0.001 | E37: =C37+D37 -> 1.861 | F37: 0.0442 | G37: =E37/((100%-F37)) -> 1.9470601 | H37: 0.15 | I37: 0.0709734 | L37: 1.7249287 | M37: =SUM(G37:L37) -> 3.8929622 | N37: 19.993573 | O37: =M37-N37 -> -16.100611
A38: =+A37+1 -> 33 | B38: KAHALGAON-II | C38: 2.702 | D38: 0.05799 | E38: =C38+D38 -> 2.75999 | F38: 0.0442 | G38: =E38/((100%-F38)) -> 2.8876229 | I38: 0 | L38: 0.92016616 | M38: =SUM(G38:L38) -> 3.8077891 | N38: 12.332956 | O38: =M38-N38 -> -8.5251667
A39: =+A38+1 -> 34 | B39: Lara | C39: 1.224 | D39: 0.002 | E39: =C39+D39 -> 1.226 | F39: 0.0442 | G39: =E39/((100%-F39)) -> 1.2826951 | I39: 0.11369475 | J39: 0.039 | L39: 2.2835364 | M39: =SUM(G39:L39) -> 3.7189263 | N39: 10.565121 | O39: =M39-N39 -> -6.8461947
A40: =+A39+1 -> 35 | B40: Khurja STPP | C40: 2.023 | D40: 0 | E40: =C40+D40 -> 2.023 | F40: 0.0442 | G40: =E40/((100%-F40)) -> 2.1165516 | I40: 0 | J40: 0 | L40: 1.3848414 | M40: =SUM(G40:L40) -> 3.501393 | N40: 2.6676964 | O40: =M40-N40 -> 0.83369665
A41: =+A40+1 -> 36 | B41: VSTPS-I | C41: 2.113 | D41: 0.0109 | E41: =C41+D41 -> 2.1239 | F41: 0.0442 | G41: =E41/((100%-F41)) -> 2.2221176 | H41: 0.15 | I41: 0.091908 | L41: 0.9173352 | M41: =SUM(G41:L41) -> 3.3813608 | N41: 25.429482 | O41: =M41-N41 -> -22.048121
...

Sheet Excl URS 3 
A1: Details of power purchase cost per unit of Thermal and Gas Power stations for MOD for the month of March 2026
A2: Sr. No. | B2: Name of Generating Stations | C2: Energy Charges Rate for MOD Purpose Rs./kwh | D2: FCA Rs./kwh | E2: Effective Energy Charges (Rs./kwh) | F2: Transmission Losses beyond MP Periphery | G2: Variable cost incl. losses | H2: Cess on Intrastate sales | I2: ED & Cess on Auxiliary Consumption | J2: Trading Margin | K2: Transmission charges | L2: FGD / Change in Law | M2: Incentive p.u. | N2: Effective rate in Rs./kwh
G4: (Rs. per kwh)
A5: A | B5: B | C5: C | D5: D | E5: E=C+D | F5: F | G5: G=E/(100%-F) | H5: H | I5: I | J5: J | K5: K | L5: L | M5: M | N5: N=sum(H:L)
A6: 1 | B6: Indira Gandhi STPS (Jhajjar) (NR) | C6: 4.158 | D6: 0.031 | E6: =C6+D6 -> 4.189 | F6: 0.0442 | G6: =E6/((100%-F6)) -> 4.382716 | I6: 0 | L6: 0.065 | N6: =SUM(G6:M6) -> 4.447716 | O6: 3.849 | P6: =N6-O6 -> 0.59871605 | Q6: =N6-N7 -> 0.0032192927 | R6: =N6-N7 -> 0.0032192927 | S6: =N6-N7 -> 0.0032192927 | T6: 3.914 | U6: =N6-T6 -> 0.53371605 | V6: 1.657 | W6: =N6-V6 -> 2.790716 | X6: 1.929 | Y6: =N6-X6 -> 2.518716 | Z6: 1.866 | AA6: =N6-Z6 -> 2.581716 | AB6: 1.913 | AC6: =N6-AB6 -> 2.534716
A7: =+A6+1 -> 2 | B7: Unchahar II (NR) | C7: 3.386 | D7: 0.19299 | E7: =C7+D7 -> 3.57899 | F7: 0.0442 | G7: =E7/((100%-F7)) -> 3.7444968 | I7: 0 | L7: 0.7 | N7: =SUM(G7:M7) -> 4.4444968 | O7: 3.415474 | P7: =N7-O7 -> 1.0290227 | Q7: =N7-#REF! -> #REF! | R7: =N7-#REF! -> #REF! | S7: =N7-#REF! -> #REF! | T7: 3.849 | U7: =N7-T7 -> 0.59549676 | V7: 4.21901 | W7: =N7-V7 -> 0.22548676 | X7: 4.39601 | Y7: =N7-X7 -> 0.048486757 | Z7: 4.12601 | AA7: =N7-Z7 -> 0.31848676 | AB7: 3.99101 | AC7: =N7-AB7 -> 0.45348676
A8: =+A7+1 -> 3 | B8: Solapur I | C8: 3.94 | D8: 0.022 | E8: =C8+D8 -> 3.962 | F8: 0.0442 | G8: =E8/((100%-F8)) -> 4.1452187 | I8: 0 | L8: 0.096 | N8: =SUM(G8:M8) -> 4.2412187 | O8: 2.9165641 | P8: =N8-O8 -> 1.3246546 | Q8: =N8-N9 -> 0.085508871 | R8: =N8-N9 -> 0.085508871 | S8: =N8-N9 -> 0.085508871 | T8: 2.8281883 | U8: =N8-T8 -> 1.4130303 | V8: 4.09701 | W8: =N8-V8 -> 0.14420866 | X8: 3.6690126 | Y8: =N8-X8 -> 0.57220604 | Z8: 3.9690348 | AA8: =N8-Z8 -> 0.27218389 | AB8: 3.002403 | AC8: =N8-AB8 -> 1.2388157
A9: =+A8+1 -> 4 | B9: Gadarwara | C9: 3.119 | D9: 0.032 | E9: =C9+D9 -> 3.151 | F9: 0.0442 | G9: =E9/((100%-F9)) -> 3.2967148 | H9: 0.15 | I9: 0.058995 | L9: 0.65 | N9: =SUM(G9:M9) -> 4.1557098 | O9: 2.872606 | P9: =N9-O9 -> 1.2831038 | Q9: =N9-N10 -> 0.031051916 | R9: =N9-N10 -> 0.031051916 | S9: =N9-N10 -> 0.031051916 | T9: 1.9803711 | U9: =N9-T9 -> 2.1753387 | V9: 4.4699081 | W9: =N9-V9 -> -0.31419833 | X9: 2.739526 | Y9: =N9-X9 -> 1.4161838 | Z9: 2.7337724 | AA9: =N9-Z9 -> 1.4219374 | AB9: 2.7136212 | AC9: =N9-AB9 -> 1.4420886
A10: =+A9+1 -> 5 | B10: National Capital Thermal Power Station Dadri II (NR) | C10: 3.72 | D10: 0.165 | E10: =C10+D10 -> 3.885 | F10: 0.0442 | G10: =E10/((100%-F10)) -> 4.0646579 | I10: 0 | L10: 0.06 | N10: =SUM(G10:M10) -> 4.1246579 | O10: 2.7761089 | P10: =N10-O10 -> 1.348549 | Q10: =N10-N11 -> 0.14264788 | R10: =N10-N11 -> 0.14264788 | S10: =N10-N11 -> 0.14264788 | T10: 2.6892371 | U10: =N10-T10 -> 1.4354208 | V10: 2.6781305 | W10: =N10-V10 -> 1.4465274 | X10: 3.7395601 | Y10: =N10-X10 -> 0.38509782 | Z10: 3.4913975 | AA10: =N10-Z10 -> 0.63326035 | AB10: 3.5141681 | AC10: =N10-AB10 -> 0.61048975
A11: =+A10+1 -> 6 | B11: BLA | C11: 3.752 | E11: =C11+D11 -> 3.752 | G11: =E11/((100%-F11)) -> 3.752 | H11: 0.15 | I11: 0.08001 | N11: =SUM(G11:M11) -> 3.98201 | O11: 3.31 | P11: =N11-O11 -> 0.67201 | Q11: =N11-N12 -> 0.2827746 | R11: =N11-N12 -> 0.2827746 | S11: =N11-N12 -> 0.2827746 | T11: 1.6656273 | U11: =N11-T11 -> 2.3163827 | V11: 5.000485 | W11: =N11-V11 -> -1.018475 | X11: 1.6507969 | Y11: =N11-X11 -> 2.3312131 | Z11: 2.2107482 | AA11: =N11-Z11 -> 1.7712618 | AB11: 2.1881519 | AC11: =N11-AB11 -> 1.7938581
A12: =+A11+1 -> 7 | B12: Unchahar I (NR) | C12: 3.35 | D12: 0.115 | E12: =C12+D12 -> 3.465 | F12: 0.0442 | G12: =E12/((100%-F12)) -> 3.6252354 | I12: 0 | L12: 0.074 | N12: =SUM(G12:M12) -> 3.6992354 | O12: 0.65704658 | P12: =N12-O12 -> 3.0421888 | Q12: =N12-N13 -> 0.010323708 | R12: =N12-N13 -> 0.010323708 | S12: =N12-N13 -> 0.010323708 | T12: 2.5527492 | U12: =N12-T12 -> 1.1464862 | V12: 2.9233935 | W12: =N12-V12 -> 0.77584194 | X12: 3.2052681 | Y12: =N12-X12 -> 0.49396734 | Z12: 3.0952055 | AA12: =N12-Z12 -> 0.60402993 | AB12: 2.8503546 | AC12: =N12-AB12 -> 0.84888079
A13: =+A12+1 -> 8 | B13: Unchahar III (NR) | C13: 3.339 | D13: 0.119 | E13: =C13+D13 -> 3.458 | F13: 0.0442 | G13: =E13/((100%-F13)) -> 3.6179117 | I13: 0 | L13: 0.071 | N13: =SUM(G13:M13) -> 3.6889117 | O13: 2.1547486 | P13: =N13-O13 -> 1.5341631 | Q13: =N13-N14 -> 0.098141697 | R13: =N13-N14 -> 0.098141697 | S13: =N13-N14 -> 0.098141697 | T13: 1.6698888 | U13: =N13-T13 -> 2.0190229 | V13: 3.85077 | W13: =N13-V13 -> -0.1618583 | X13: 3.11177 | Y13: =N13-X13 -> 0.5771417 | Z13: 3.22177 | AA13: =N13-Z13 -> 0.4671417 | AB13: 3.59077 | AC13: =N13-AB13 -> 0.098141697
A14: =+A13+1 -> 9 | B14: JP Bina | C14: 3.376 | E14: =C14+D14 -> 3.376 | G14: =E14/((100%-F14)) -> 3.376 | H14: 0.15 | I14: 0.06477 | N14: =SUM(G14:M14) -> 3.59077 | O14: 2.872606 | P14: =N14-O14 -> 0.71816396 | Q14: =N14-N16 -> 0.020985526 | R14: =N14-N16 -> 0.020985526 | S14: =N14-N16 -> 0.020985526 | T14: 2.6954734 | U14: =N14-T14 -> 0.89529656 | V14: 0.80423025 | W14: =N14-V14 -> 2.7865397 | X14: 0.82030928 | Y14: =N14-X14 -> 2.7704607 | Z14: 0.92340858 | AA14: =N14-Z14 -> 2.6673614 | AB14: 0.89922486 | AC14: =N14-AB14 -> 2.6915451
A15: =+A14+1 -> 10 | B15: Khargone | C15: 3.201 | D15: -0.023 | E15: =C15+D15 -> 3.178 | F15: 0.0442 | G15: =E15/((100%-F15)) -> 3.3249634 | H15: 0.15 | I15: 0.052785 | L15: 0.062 | N15: =SUM(G15:M15) -> 3.5897484 | Z15: 2.9314963 | AA15: =N15-Z15 -> 0.65825207 | AB15: 2.8785878 | AC15: =N15-AB15 -> 0.71116056
A16: =+A15+1 -> 11 | B16: Ghatampur Thermal Power Station (NUPPL) | C16: 3.412 | E16: =C16+D16 -> 3.412 | F16: 0.0442 | G16: =E16/((100%-F16)) -> 3.5697845 | N16: =SUM(G16:M16) -> 3.5697845 | O16: 2.9216755 | P16: =N16-O16 -> 0.64810901 | Q16: =N16-N17 -> 0.018745763 | R16: =N16-N17 -> 0.018745763 | S16: =N16-N17 -> 0.018745763 | T16: 3.372 | U16: =N16-T16 -> 0.19778447 | V16: 4.0528543 | W16: =N16-V16 -> -0.48306987 | X16: 3.1649762 | Y16: =N16-X16 -> 0.40480828 | Z16: 1.682824 | AA16: =N16-Z16 -> 1.8869604 | AB16: 1.6656237 | AC16: =N16-AB16 -> 1.9041608
A17: =+A16+1 -> 12 | B17: Unchahar IV (NR) | C17: 3.173 | D17: 0.158 | E17: =C17+D17 -> 3.331 | F17: 0.0442 | G17: =E17/((100%-F17)) -> 3.4850387 | I17: 0 | L17: 0.066 | N17: =SUM(G17:M17) -> 3.5510387 | O17: 1.5871379 | P17: =N17-O17 -> 1.9639008 | Q17: =N17-N18 -> 0.080745763 | R17: =N17-N18 -> 0.080745763 | S17: =N17-N18 -> 0.080745763 | T17: 0.70503586 | U17: =N17-T17 -> 2.8460029 | V17: 1.650989 | W17: =N17-V17 -> 1.9000497 | X17: 1.6528669 | Y17: =N17-X17 -> 1.8981718 | Z17: 3.8486111 | AA17: =N17-Z17 -> -0.29757242 | AB17: 3.7075873 | AC17: =N17-AB17 -> -0.15654854
A18: =+A17+1 -> 13 | B18: DVC (DTPS) (STOA LOI) | C18: 3.085 | D18: 0.165 | E18: =C18+D18 -> 3.25 | F18: 0.0442 | G18: =E18/((100%-F18)) -> 3.4002929 | I18: 0 | K18: 0 | L18: 0.07 | N18: =SUM(G18:M18) -> 3.4702929 | O18: 1.5590809 | P18: =N18-O18 -> 1.9112121 | Q18: =N18-N15 -> -0.11945543 | R18: =N18-N15 -> -0.11945543 | S18: =N18-N15 -> -0.11945543 | T18: 2.1505041 | U18: =N18-T18 -> 1.3197888 | V18: 1.6072498 | W18: =N18-V18 -> 1.8630432 | X18: 3.9069721 | Y18: =N18-X18 -> -0.43667913 | Z18: 1.4397759 | AA18: =N18-Z18 -> 2.030517 | AB18: 1.4608279 | AC18: =N18-AB18 -> 2.009465
A19: =+A18+1 -> 14 | B19: Tanda II | C19: 2.851 | D19: 0.063 | E19: =C19+D19 -> 2.914 | F19: 0.0442 | G19: =E19/((100%-F19)) -> 3.048755 | I19: 0 | K19: 0.23259 | L19: 0.064 | N19: =SUM(G19:M19) -> 3.345345 | O19: 2.4071804 | P19: =N19-O19 -> 0.93816455 | Q19: =N19-N20 -> 0.0078266604 | R19: =N19-N20 -> 0.0078266604 | S19: =N19-N20 -> 0.0078266604 | T19: 2.6057582 | U19: =N19-T19 -> 0.73958673 | V19: 3.9901661 | W19: =N19-V19 -> -0.64482116 | X19: 1.4282624 | Y19: =N19-X19 -> 1.9170826 | Z19: 1.3981942 | AA19: =N19-Z19 -> 1.9471507 | AB19: 1.4163543 | AC19: =N19-AB19 -> 1.9289906
A20: =+A19+1 -> 15 | B20: Mauda-I | C20: 3.226 | D20: -0.036 | E20: =C20+D20 -> 3.19 | F20: 0.0442 | G20: =E20/((100%-F20)) -> 3.3375183 | I20: 0 | N20: =SUM(G20:M20) -> 3.3375183 | O20: 3.4208333 | P20: =N20-O20 -> -0.083314982 | Q20: =N20-N21 -> 0.0052711864 | R20: =N20-N21 -> 0.0052711864 | S20: =N20-N21 -> 0.0052711864 | T20: 1.6800748 | U20: =N20-T20 -> 1.6574435 | V20: 3.3451423 | W20: =N20-V20 -> -0.0076239819 | X20: 2.1743698 | Y20: =N20-X20 -> 1.1631485 | Z20: 2.3230223 | AA20: =N20-Z20 -> 1.014496 | AB20: 2.0234159 | AC20: =N20-AB20 -> 1.3141024
A21: =+A20+1 -> 16 | B21: Mauda-II | C21: 3.152 | D21: -0.0349 | E21: =C21+D21 -> 3.1171 | F21: 0.0442 | G21: =E21/((100%-F21)) -> 3.2612471 | I21: 0 | L21: 0.071 | N21: =SUM(G21:M21) -> 3.3322471 | O21: 3.4980879 | P21: =N21-O21 -> -0.16584076 | Q21: =N21-N22 -> 0.0051561258 | R21: =N21-N22 -> 0.0051561258 | S21: =N21-N22 -> 0.0051561258 | T21: 2.8181218 | U21: =N21-T21 -> 0.51412531 | V21: 1.5394732 | W21: =N21-V21 -> 1.7927739 | X21: 1.5617854 | Y21: =N21-X21 -> 1.7704617 | Z21: 1.3907327 | AA21: =N21-Z21 -> 1.9415144 | AB21: 1.4229467 | AC21: =N21-AB21 -> 1.9093004
A22: =+A21+1 -> 17 | B22: MB Power | C22: 2.951 | E22: =C22+D22 -> 2.951 | F22: 0.0442 | G22: =E22/((100%-F22)) -> 3.087466 | H22: 0.15 | I22: 0.047625 | L22: 0.042 | N22: =SUM(G22:M22) -> 3.327091 | O22: 2.5944007 | P22: =N22-O22 -> 0.73269032 | Q22: =N22-N23 -> 0.200091 | R22: =N22-N23 -> 0.200091 | S22: =N22-N23 -> 0.200091 | T22: 1.5424592 | U22: =N22-T22 -> 1.7846318 | V22: 2.052 | W22: =N22-V22 -> 1.275091 | X22: 3.2819292 | Y22: =N22-X22 -> 0.04516179 | Z22: 3.0273973 | AA22: =N22-Z22 -> 0.29969374 | AB22: 3.2644973 | AC22: =N22-AB22 -> 0.062593709
A23: =+A22+1 -> 18 | B23: SSTPS Khandwa (Singaji) | C23: 3.126 | D23: 0.001 | E23: =C23+D23 -> 3.127 | G23: =E23/((100%-F23)) -> 3.127 | I23: 0 | N23: =SUM(G23:M23) -> 3.127 | O23: 2.5933627 | P23: =N23-O23 -> 0.53363728 | Q23: =N23-N24 -> 0.033256539 | R23: =N23-N24 -> 0.033256539 | S23: =N23-N24 -> 0.033256539 | T23: 1.5112774 | U23: =N23-T23 -> 1.6157226 | V23: 2.601 | W23: =N23-V23 -> 0.526 | X23: 3.353343 | Y23: =N23-X23 -> -0.22634299 | Z23: 3.0010537 | AA23: =N23-Z23 -> 0.12594626 | AB23: 3.2458281 | AC23: =N23-AB23 -> -0.11882812
A24: =+A23+1 -> 19 | B24: Meja (NR) | C24: 2.966 | D24: -0.009 | E24: =C24+D24 -> 2.957 | F24: 0.0442 | G24: =E24/((100%-F24)) -> 3.0937435 | I24: 0 | N24: =SUM(G24:M24) -> 3.0937435 | O24: 1.5003771 | P24: =N24-O24 -> 1.5933663 | Q24: =N24-N26 -> 0.043942247 | R24: =N24-N26 -> 0.043942247 | S24: =N24-N26 -> 0.043942247 | T24: 1.8335984 | U24: =N24-T24 -> 1.2601451 | V24: 3.2283224 | W24: =N24-V24 -> -0.1345789 | X24: 3.1048906 | Y24: =N24-X24 -> -0.011147116 | Z24: 3.0963163 | AA24: =N24-Z24 -> -0.002572793 | AB24: 3.230864 | AC24: =N24-AB24 -> -0.13712059
A25: =+A24+1 -> 20 | B25: SGTPS -4x210 | C25: 3.064 | D25: 0.003 | E25: =C25+D25 -> 3.067 | G25: =E25/((100%-F25)) -> 3.067 | I25: 0 | N25: =SUM(G25:M25) -> 3.067 | Z25: 1.564657 | AA25: =N25-Z25 -> 1.502343 | AB25: 1.552276 | AC25: =N25-AB25 -> 1.514724
A26: =+A25+1 -> 21 | B26: TRN Energy Pvt. Ltd. (Medium Term) | C26: 3.101 | D26: -0.186 | E26: =C26+D26 -> 2.915 | F26: 0.0442 | G26: =E26/((100%-F26)) -> 3.0498012 | N26: =SUM(G26:M26) -> 3.0498012 | O26: 1.907 | P26: =N26-O26 -> 1.1428012 | Q26: =N26-#REF! -> #REF! | R26: =N26-#REF! -> #REF! | S26: =N26-#REF! -> #REF! | T26: 2.1025881 | U26: =N26-T26 -> 0.94721313 | V26: 3.4801031 | W26: =N26-V26 -> -0.43030189 | X26: 1.5429562 | Y26: =N26-X26 -> 1.506845 | Z26: 2.339 | AA26: =N26-Z26 -> 0.71080121 | AB26: 2.374 | AC26: =N26-AB26 -> 0.67580121
A27: =+A26+1 -> 22 | B27: SSTPS Khandwa (Singaji) # 3 & 4 | C27: 2.927 | D27: -0.001 | E27: =C27+D27 -> 2.926 | G27: =E27/((100%-F27)) -> 2.926 | I27: 0 | N27: =SUM(G27:M27) -> 2.926 | Z27: 2.98 | AA27: =N27-Z27 -> -0.054 | AB27: 3.061 | AC27: =N27-AB27 -> -0.135
A28: =+A27+1 -> 23 | B28: KAHALGAON-II | C28: 2.702 | D28: 0.05799 | E28: =C28+D28 -> 2.75999 | F28: 0.0442 | G28: =E28/((100%-F28)) -> 2.8876229 | I28: 0 | N28: =SUM(G28:M28) -> 2.8876229 | O28: 1.6171688 | P28: =N25-O28 -> 1.4498312 | Q28: =N25-N29 -> 0.18355158 | R28: =N25-N29 -> 0.18355158 | S28: =N25-N29 -> 0.18355158 | T28: 3.0703669 | U28: =N25-T28 -> -0.0033669057 | V28: 3.465 | W28: =N25-V28 -> -0.398 | X28: 2.841 | Y28: =N25-X28 -> 0.226 | Z28: 1.5269496 | AA28: =N28-Z28 -> 1.3606734 | AB28: 1.407984 | AC28: =N28-AB28 -> 1.4796389
A29: =+A28+1 -> 24 | B29: SKS Power Generation (Medium Term) | C29: 2.756 | E29: =C29+D29 -> 2.756 | F29: 0.0442 | G29: =E29/((100%-F29)) -> 2.8834484 | N29: =SUM(G29:M29) -> 2.8834484 | O29: 1.6656119 | P29: =N29-O29 -> 1.2178365 | Q29: =N29-N27 -> -0.04255158 | R29: =N29-N27 -> -0.04255158 | S29: =N29-N27 -> -0.04255158 | T29: 2.6528583 | U29: =N29-T29 -> 0.23059009 | V29: 3.115 | W29: =N29-V29 -> -0.23155158 | X29: 3.088 | Y29: =N29-X29 -> -0.20455158 | Z29: 1.5270992 | AA29: =N29-Z29 -> 1.3563492 | AB29: 1.4125739 | AC29: =N29-AB29 -> 1.4708745
A30: =+A29+1 -> 25 | B30: Jhabua Power | C30: 2.606 | D30: -0.0099 | E30: =C30+D30 -> 2.5961 | F30: 0.0442 | G30: =E30/((100%-F30)) -> 2.716154 | H30: 0.15 | N30: =SUM(G30:M30) -> 2.866154 | O30: 2.681 | P30: =N30-O30 -> 0.18515401 | Q30: =N30-N31 -> 0.080154007 | R30: =N30-N31 -> 0.080154007 | S30: =N30-N31 -> 0.080154007 | T30: 1.5141564 | U30: =N30-T30 -> 1.3519976 | V30: 1.8737889 | W30: =N30-V30 -> 0.99236515 | X30: 4.9058063 | Y30: =N30-X30 -> -2.0396522 | Z30: 4.8413804 | AA30: =N30-Z30 -> -1.9752264 | AB30: 4.2489791 | AC30: =N30-AB30 -> -1.3828251
A31: =+A30+1 -> 26 | B31: STPS Sarni 10 & 11 | C31: 2.779 | D31: 0.007 | E31: =C31+D31 -> 2.786 | G31: =E31/((100%-F31)) -> 2.786 | I31: 0 | N31: =SUM(G31:M31) -> 2.786 | O31: 2.781 | P31: =N31-O31 -> 0.005 | Q31: =N31-N32 -> 0.0009738439 | R31: =N31-N32 -> 0.0009738439 | S31: =N31-N32 -> 0.0009738439 | T31: 1.998 | U31: =N31-T31 -> 0.788 | V31: 1.7904668 | W31: =N31-V31 -> 0.99553321 | X31: 3.306 | Y31: =N31-X31 -> -0.52 | Z31: 3.102 | AA31: =N31-Z31 -> -0.316 | AB31: 3.177 | AC31: =N31-AB31 -> -0.391
A32: =+A31+1 -> 27 | B32: Jindal Power Limited (Medium Term) | C32: 2.67 | D32: -0.161 | E32: =C32+D32 -> 2.509 | F32: 0.0442 | G32: =E32/((100%-F32)) -> 2.6250262 | L32: 0.16 | N32: =SUM(G32:M32) -> 2.7850262 | O32: 2.332 | P32: =N32-O32 -> 0.45302616 | Q32: =N32-N33 -> 0.063358443 | R32: =N32-N33 -> 0.063358443 | S32: =N32-N33 -> 0.063358443 | T32: 2.368 | U32: =N32-T32 -> 0.41702616 | V32: 1.7731048 | W32: =N32-V32 -> 1.0119214 | X32: 3.011 | Y32: =N32-X32 -> -0.22597384 | Z32: 3.039 | AA32: =N32-Z32 -> -0.25397384 | AB32: 2.89 | AC32: =N32-AB32 -> -0.10497384
A33: =+A32+1 -> 28 | B33: Mahan Energen Ltd. (5%) | C33: 2.488 | D33: -0.03 | E33: =C33+D33 -> 2.458 | F33: 0.0442 | G33: =E33/((100%-F33)) -> 2.5716677 | H33: 0.15 | I33: 0 | N33: =SUM(G33:M33) -> 2.7216677 | O33: 2.0943216 | P33: =N33-O33 -> 0.62734611 | Q33: =N33-N34 -> 0.033343796 | R33: =N33-N34 -> 0.033343796 | S33: =N33-N34 -> 0.033343796 | T33: 1.5486956 | U33: =N33-T33 -> 1.1729722 | V33: 1.7534908 | W33: =N33-V33 -> 0.96817687 | X33: 3.614 | Y33: =N33-X33 -> -0.89233229 | Z33: 2.936 | AA33: =N33-Z33 -> -0.21433229 | AB33: 2.921 | AC33: =N33-AB33 -> -0.19933229
A34: =+A33+1 -> 29 | B34: RKM Powergen (Talcher Field) (Medium Term) | C34: 2.5695 | E34: =C34+D34 -> 2.5695 | F34: 0.0442 | G34: =E34/((100%-F34)) -> 2.6883239 | N34: =SUM(G34:M34) -> 2.6883239 | O34: 2.0259908 | P34: =N34-O34 -> 0.6623331 | Q34: =N34-N35 -> 0.047080979 | R34: =N34-N35 -> 0.047080979 | S34: =N34-N35 -> 0.047080979 | T34: 1.5964972 | U34: =N34-T34 -> 1.0918267 | V34: 1.8088725 | W34: =N34-V34 -> 0.87945138 | X34: 2.872 | Y34: =N34-X34 -> -0.18367608 | Z34: 2.6042895 | AA34: =N34-Z34 -> 0.084034463 | AB34: 2.5655417 | AC34: =N34-AB34 -> 0.12278221
A35: =+A34+1 -> 30 | B35: RKM Powergen (IB Field) (Medium Term) | C35: 2.5245 | E35: =C35+D35 -> 2.5245 | F35: 0.0442 | G35: =E35/((100%-F35)) -> 2.6412429 | N35: =SUM(G35:M35) -> 2.6412429 | O35: 2.0094258 | P35: =N35-O35 -> 0.63181716 | Q35: =N35-N36 -> 0.093638837 | R35: =N35-N36 -> 0.093638837 | S35: =N35-N36 -> 0.093638837 | T35: 3.0620518 | U35: =N35-T35 -> -0.42080882 | V35: 2.0703685 | W35: =N35-V35 -> 0.5708744 | X35: 1.8834486 | Y35: =N35-X35 -> 0.75779436 | Z35: 2.4677843 | AA35: =N35-Z35 -> 0.17345866 | AB35: 2.800176 | AC35: =N35-AB35 -> -0.1589331
A36: =+A35+1 -> 31 | B36: Jindal India Thermal Power (Medium Term) | C36: 2.435 | E36: =C36+D36 -> 2.435 | F36: 0.0442 | G36: =E36/((100%-F36)) -> 2.5476041 | N36: =SUM(G36:M36) -> 2.5476041 | O36: 1.9866488 | P36: =N36-O36 -> 0.56095526 | Q36: =N36-N38 -> 0.1506041 | R36: =N36-N38 -> 0.1506041 | S36: =N36-N38 -> 0.1506041 | T36: 2.855 | U36: =N36-T36 -> -0.3073959 | V36: 2.1523692 | W36: =N36-V36 -> 0.39523495 | X36: 1.8027052 | Y36: =N36-X36 -> 0.74489889 | Z36: 2.475542 | AA36: =N36-Z36 -> 0.07206213 | AB36: 2.4401287 | AC36: =N36-AB36 -> 0.10747542
A37: =+A36+1 -> 32 | B37: VSTPS-I | C37: 2.113 | D37: 0.0109 | E37: =C37+D37 -> 2.1239 | F37: 0.0442 | G37: =E37/((100%-F37)) -> 2.2221176 | H37: 0.15 | I37: 0.091908 | N37: =SUM(G37:M37) -> 2.4640256 | Z37: 2.4502522 | AA37: =N37-Z37 -> 0.013773405 | AB37: 2.4140974 | AC37: =N37-AB37 -> 0.049928208
A38: =+A37+1 -> 33 | B38: SGTPS -1x500 | C38: 2.399 | D38: -0.002 | E38: =C38+D38 -> 2.397 | G38: =E38/((100%-F38)) -> 2.397 | I38: 0 | N38: =SUM(G38:M38) -> 2.397 | O38: 2.0425559 | P38: =N38-O38 -> 0.35444414 | Q38: =N38-N37 -> -0.067025598 | R38: =N38-N37 -> -0.067025598 | S38: =N38-N37 -> -0.067025598 | T38: 2.71 | U38: =N38-T38 -> -0.313 | V38: 2.1492722 | W38: =N38-V38 -> 0.24772778 | X38: 1.7800384 | Y38: =N38-X38 -> 0.61696164 | Z38: 2.4917848 | AA38: =N38-Z38 -> -0.09478478 | AB38: 2.4571019 | AC38: =N38-AB38 -> -0.060101894
A39: =+A38+1 -> 34 | B39: VSTPS-II | C39: 2.024 | D39: -0.0009 | E39: =C39+D39 -> 2.0231 | F39: 0.0442 | G39: =E39/((100%-F39)) -> 2.1166562 | H39: 0.15 | I39: 0.0668886 | L39: 0.037 | N39: =SUM(G39:M39) -> 2.3705448 | O39: 3.7038663 | P39: =N39-O39 -> -1.3333215 | Q39: =N39-N40 -> 0.0079099688 | R39: =N39-N40 -> 0.0079099688 | S39: =N39-N40 -> 0.0079099688 | T39: 2.588 | U39: =N39-T39 -> -0.2174552 | V39: 1.6238257 | W39: =N39-V39 -> 0.74671906 | X39: 1.8274932 | Y39: =N39-X39 -> 0.54305158 | Z39: 2.1127503 | AA39: =N39-Z39 -> 0.25779454 | AB39: 2.0911556 | AC39: =N39-AB39 -> 0.27938919
A40: =+A39+1 -> 35 | B40: VSTPS-V | C40: 2.048 | D40: -0.001 | E40: =C40+D40 -> 2.047 | F40: 0.0442 | G40: =E40/((100%-F40)) -> 2.1416614 | H40: 0.15 | I40: 0.0709734 | N40: =SUM(G40:M40) -> 2.3626348 | O40: 3.5840426 | P40: =N40-O40 -> -1.2214077 | Q40: =N40-N41 -> 0.020150403 | R40: =N40-N41 -> 0.020150403 | S40: =N40-N41 -> 0.020150403 | T40: 2.1061376 | U40: =N40-T40 -> 0.25649722 | V40: 1.6062765 | W40: =N40-V40 -> 0.75635838 | X40: 2.0751397 | Y40: =N40-X40 -> 0.28749511 | Z40: 2.1970495 | AA40: =N40-Z40 -> 0.16558531 | AB40: 2.1745932 | AC40: =N40-AB40 -> 0.18804159
A41: =+A40+1 -> 36 | B41: VSTPS-III | C41: 2.007 | D41: -0.001 | E41: =C41+D41 -> 2.006 | F41: 0.0442 | G41: =E41/((100%-F41)) -> 2.0987654 | H41: 0.15 | I41: 0.058719 | L41: 0.035 | N41: =SUM(G41:M41) -> 2.3424844 | O41: 3.7238268 | P41: =N41-O41 -> -1.3813423 | Q41: =N41-N42 -> 0.023063612 | R41: =N41-N42 -> 0.023063612 | S41: =N41-N42 -> 0.023063612 | T41: 2.0333697 | U41: =N41-T41 -> 0.30911472 | V41: 1.5856302 | W41: =N41-V41 -> 0.75685421 | X41: 2.1579383 | Y41: =N41-X41 -> 0.18454612 | Z41: 2.1601686 | AA41: =N41-Z41 -> 0.18231583 | AB41: 2.1380893 | AC41: =N41-AB41 -> 0.20439515
...

Sheet  Rate sheet  2
A1: ='Excl URS 3 '!A1:N1 -> Details of power purchase cost per unit of Thermal and Gas Power stations for MOD for the month of March 2026
A2: Sr. No. | B2: Name of Generating Stations | C2: Installed Capacity (MW) | D2: MPPMCL Share (MW) | E2: Cumulative capacity (MW) | F2: Normative Fixed Cost Rs. /kwh | G2: Variable rate at MP periphery in Rs./kwh | H2: Total rate (Fixed & Variable) Rs./ Kwh
A3: 1 | B3: KAWAS (NAPM) | C3: =VLOOKUP(B3,'rate sheet working'!$B$3:$C$158,2,0) -> 0 | D3: =VLOOKUP(B3,'rate sheet working'!$B$3:$D$158,3,0) -> 0 | E3: =D3+E4 -> 13028.414 | F3: =VLOOKUP(B3,'rate sheet working'!$B$3:$E$158,4,0) -> 0.85915096 | G3: =VLOOKUP(B3,'rate sheet periphery 1'!$B$5:$F$110,5,0) -> 37.274534 | H3: =F3+G3 -> 38.133685
A4: 2 | B4: GANDHAR (NAPM) | C4: =VLOOKUP(B4,'rate sheet working'!$B$3:$C$158,2,0) -> 0 | D4: =VLOOKUP(B4,'rate sheet working'!$B$3:$D$158,3,0) -> 0 | E4: =D4+E5 -> 13028.414 | F4: =VLOOKUP(B4,'rate sheet working'!$B$3:$E$158,4,0) -> 1.0465902 | G4: =VLOOKUP(B4,'rate sheet periphery 1'!$B$5:$F$110,5,0) -> 31.092279 | H4: =F4+G4 -> 32.138869 | I4: =H4-H5 -> 6.1248739
A5: 3 | B5: KAWAS (Liquid) | C5: =VLOOKUP(B5,'rate sheet working'!$B$3:$C$158,2,0) -> 0 | D5: =VLOOKUP(B5,'rate sheet working'!$B$3:$D$158,3,0) -> 0 | E5: =D5+E6 -> 13028.414 | F5: =VLOOKUP(B5,'rate sheet working'!$B$3:$E$158,4,0) -> 0.85915096 | G5: =VLOOKUP(B5,'rate sheet periphery 1'!$B$5:$F$110,5,0) -> 25.154844 | H5: =F5+G5 -> 26.013995 | I5: =H5-H6 -> 0.50635912
A6: 4 | B6: Dadri Liquid (NR) | C6: =VLOOKUP(B6,'rate sheet working'!$B$3:$C$158,2,0) -> 0 | D6: =VLOOKUP(B6,'rate sheet working'!$B$3:$D$158,3,0) -> 0 | E6: =D6+E7 -> 13028.414 | F6: =VLOOKUP(B6,'rate sheet working'!$B$3:$E$158,4,0) -> 0.52960707 | G6: =VLOOKUP(B6,'rate sheet periphery 1'!$B$5:$F$110,5,0) -> 24.978029 | H6: =F6+G6 -> 25.507636 | I6: =H6-H7 -> 5.3193821
A7: 5 | B7: Auraiya Liquid (NR) | C7: =VLOOKUP(B7,'rate sheet working'!$B$3:$C$158,2,0) -> 0 | D7: =VLOOKUP(B7,'rate sheet working'!$B$3:$D$158,3,0) -> 0 | E7: =D7+E8 -> 13028.414 | F7: =VLOOKUP(B7,'rate sheet working'!$B$3:$E$158,4,0) -> 0.635 | G7: =VLOOKUP(B7,'rate sheet periphery 1'!$B$5:$F$110,5,0) -> 19.553254 | H7: =F7+G7 -> 20.188254
A8: 6 | B8: Anta Liquid (NR) | C8: =VLOOKUP(B8,'rate sheet working'!$B$3:$C$158,2,0) -> 0 | D8: =VLOOKUP(B8,'rate sheet working'!$B$3:$D$158,3,0) -> 0 | E8: =D8+E9 -> 13028.414 | F8: =VLOOKUP(B8,'rate sheet working'!$B$3:$E$158,4,0) -> 0.709 | G8: =VLOOKUP(B8,'rate sheet periphery 1'!$B$5:$F$110,5,0) -> 18.307177 | H8: =F8+G8 -> 19.016177
A9: 7 | B9: GANDHAR (LNG) | C9: =VLOOKUP(B9,'rate sheet working'!$B$3:$C$158,2,0) -> 0 | D9: =VLOOKUP(B9,'rate sheet working'!$B$3:$D$158,3,0) -> 0 | E9: =D9+E10 -> 13028.414 | F9: =VLOOKUP(B9,'rate sheet working'!$B$3:$E$158,4,0) -> 1.0465902 | G9: =VLOOKUP(B9,'rate sheet periphery 1'!$B$5:$F$110,5,0) -> 13.649299 | H9: =F9+G9 -> 14.695889 | I9: =H9-H10 -> 1.225568
A10: 8 | B10: Auraiya CLNG (NR) | C10: =VLOOKUP(B10,'rate sheet working'!$B$3:$C$158,2,0) -> 0 | D10: =VLOOKUP(B10,'rate sheet working'!$B$3:$D$158,3,0) -> 0 | E10: =D10+E11 -> 13028.414 | F10: =VLOOKUP(B10,'rate sheet working'!$B$3:$E$158,4,0) -> 0.635 | G10: =VLOOKUP(B10,'rate sheet periphery 1'!$B$5:$F$110,5,0) -> 12.835321 | H10: =F10+G10 -> 13.470321 | I10: =H10-H11 -> 0.71744566
A11: 9 | B11: Dadri Comm LNG (NR) | C11: =VLOOKUP(B11,'rate sheet working'!$B$3:$C$158,2,0) -> 0 | D11: =VLOOKUP(B11,'rate sheet working'!$B$3:$D$158,3,0) -> 0 | E11: =D11+E12 -> 13028.414 | F11: =VLOOKUP(B11,'rate sheet working'!$B$3:$E$158,4,0) -> 0.52960707 | G11: =VLOOKUP(B11,'rate sheet periphery 1'!$B$5:$F$110,5,0) -> 12.223268 | H11: =F11+G11 -> 12.752876 | I11: =H11-#REF! -> #REF!
A12: 10 | B12: Auraiya LNG (NR) | C12: =VLOOKUP(B12,'rate sheet working'!$B$3:$C$158,2,0) -> 0 | D12: =VLOOKUP(B12,'rate sheet working'!$B$3:$D$158,3,0) -> 0 | E12: =D12+E13 -> 13028.414 | F12: =VLOOKUP(B12,'rate sheet working'!$B$3:$E$158,4,0) -> 0.635 | G12: =VLOOKUP(B12,'rate sheet periphery 1'!$B$5:$F$110,5,0) -> 11.929274 | H12: =F12+G12 -> 12.564274
A13: 11 | B13: Anta LNG (NR) | C13: =VLOOKUP(B13,'rate sheet working'!$B$3:$C$158,2,0) -> 0 | D13: =VLOOKUP(B13,'rate sheet working'!$B$3:$D$158,3,0) -> 0 | E13: =D13+E14 -> 13028.414 | F13: =VLOOKUP(B13,'rate sheet working'!$B$3:$E$158,4,0) -> 0.709 | G13: =VLOOKUP(B13,'rate sheet periphery 1'!$B$5:$F$110,5,0) -> 11.786985 | H13: =F13+G13 -> 12.495985 | I13: =H13-H14 -> 0.60521423
A14: 12 | B14: Dadri LNG (NR) | C14: =VLOOKUP(B14,'rate sheet working'!$B$3:$C$158,2,0) -> 0 | D14: =VLOOKUP(B14,'rate sheet working'!$B$3:$D$158,3,0) -> 0 | E14: =D14+E15 -> 13028.414 | F14: =VLOOKUP(B14,'rate sheet working'!$B$3:$E$158,4,0) -> 0.52960707 | G14: =VLOOKUP(B14,'rate sheet periphery 1'!$B$5:$F$110,5,0) -> 11.361163 | H14: =F14+G14 -> 11.89077 | I14: =H14-H15 -> 1.0106947
A15: 13 | B15: KAWAS (LNG) | C15: =VLOOKUP(B15,'rate sheet working'!$B$3:$C$158,2,0) -> 0 | D15: =VLOOKUP(B15,'rate sheet working'!$B$3:$D$158,3,0) -> 0 | E15: =D15+E16 -> 13028.414 | F15: =VLOOKUP(B15,'rate sheet working'!$B$3:$E$158,4,0) -> 0.85915096 | G15: =VLOOKUP(B15,'rate sheet periphery 1'!$B$5:$F$110,5,0) -> 10.020925 | H15: =F15+G15 -> 10.880076 | I15: =H15-#REF! -> #REF!
A16: 14 | B16: GANDHAR (CLNG) | C16: =VLOOKUP(B16,'rate sheet working'!$B$3:$C$158,2,0) -> 0 | D16: =VLOOKUP(B16,'rate sheet working'!$B$3:$D$158,3,0) -> 0 | E16: =D16+E17 -> 13028.414 | F16: =VLOOKUP(B16,'rate sheet working'!$B$3:$E$158,4,0) -> 1.0465902 | G16: =VLOOKUP(B16,'rate sheet periphery 1'!$B$5:$F$110,5,0) -> 9.3272651 | H16: =F16+G16 -> 10.373855 | I16: =H16-H17 -> 0.050919376
A17: 15 | B17: Anta CLNG (NR) | C17: =VLOOKUP(B17,'rate sheet working'!$B$3:$C$158,2,0) -> 0 | D17: =VLOOKUP(B17,'rate sheet working'!$B$3:$D$158,3,0) -> 0 | E17: =D17+E18 -> 13028.414 | F17: =VLOOKUP(B17,'rate sheet working'!$B$3:$E$158,4,0) -> 0.709 | G17: =VLOOKUP(B17,'rate sheet periphery 1'!$B$5:$F$110,5,0) -> 9.613936 | H17: =F17+G17 -> 10.322936
A18: 16 | B18: KAWAS (CLNG) | C18: =VLOOKUP(B18,'rate sheet working'!$B$3:$C$158,2,0) -> 0 | D18: =VLOOKUP(B18,'rate sheet working'!$B$3:$D$158,3,0) -> 0 | E18: =D18+E19 -> 13028.414 | F18: =VLOOKUP(B18,'rate sheet working'!$B$3:$E$158,4,0) -> 0.85915096 | G18: =VLOOKUP(B18,'rate sheet periphery 1'!$B$5:$F$110,5,0) -> 9.3680686 | H18: =F18+G18 -> 10.22722 | I18: =H18-H19 -> 1.6546698
A19: 17 | B19: Torrent (Indigenous) | C19: =VLOOKUP(B19,'rate sheet working'!$B$3:$C$158,2,0) -> 1115.9438 | D19: =VLOOKUP(B19,'rate sheet working'!$B$3:$D$158,3,0) -> 50 | E19: =D19+E20 -> 13028.414 | F19: =VLOOKUP(B19,'rate sheet working'!$B$3:$E$158,4,0) -> 0.89460463 | G19: =VLOOKUP(B19,'rate sheet periphery 1'!$B$5:$F$110,5,0) -> 7.6779452 | H19: =F19+G19 -> 8.5725498 | I19: =H19-H20 -> 1.6064572
A20: 18 | B20: Ghatampur Thermal Power Station (NUPPL) | C20: =VLOOKUP(B20,'rate sheet working'!$B$3:$C$158,2,0) -> 660 | D20: =VLOOKUP(B20,'rate sheet working'!$B$3:$D$158,3,0) -> 1.0626 | E20: =D20+E21 -> 12978.414 | F20: =VLOOKUP(B20,'rate sheet working'!$B$3:$E$158,4,0) -> 3.3963081 | G20: =VLOOKUP(B20,'rate sheet periphery 1'!$B$5:$F$110,5,0) -> 3.5697845 | H20: =F20+G20 -> 6.9660926 | I20: =H20-H22 -> 0.75023666
A21: 19 | B21: Solapur I | C21: =VLOOKUP(B21,'rate sheet working'!$B$3:$C$158,2,0) -> 1320 | D21: =VLOOKUP(B21,'rate sheet working'!$B$3:$D$158,3,0) -> 295.88 | E21: =D21+E22 -> 12977.351 | F21: =VLOOKUP(B21,'rate sheet working'!$B$3:$E$158,4,0) -> 1.9962859 | G21: =VLOOKUP(B21,'rate sheet periphery 1'!$B$5:$F$110,5,0) -> 4.2412187 | H21: =F21+G21 -> 6.2375045 | I21: =H21-H23 -> 0.22978847
A22: 20 | B22: Gadarwara | C22: =VLOOKUP(B22,'rate sheet working'!$B$3:$C$158,2,0) -> 1600 | D22: =VLOOKUP(B22,'rate sheet working'!$B$3:$D$158,3,0) -> 800 | E22: =D22+E23 -> 12681.471 | F22: =VLOOKUP(B22,'rate sheet working'!$B$3:$E$158,4,0) -> 2.0601461 | G22: =VLOOKUP(B22,'rate sheet periphery 1'!$B$5:$F$110,5,0) -> 4.1557098 | H22: =F22+G22 -> 6.2158559
A23: 21 | B23: Indira Gandhi STPS (Jhajjar) (NR) | C23: =VLOOKUP(B23,'rate sheet working'!$B$3:$C$158,2,0) -> 1500 | D23: =VLOOKUP(B23,'rate sheet working'!$B$3:$D$158,3,0) -> 1.8 | E23: =D23+E24 -> 11881.471 | F23: =VLOOKUP(B23,'rate sheet working'!$B$3:$E$158,4,0) -> 1.56 | G23: =VLOOKUP(B23,'rate sheet periphery 1'!$B$5:$F$110,5,0) -> 4.447716 | H23: =F23+G23 -> 6.007716 | I23: =H23-H25 -> 0.34482158
A24: 22 | B24: BLA | C24: =VLOOKUP(B24,'rate sheet working'!$B$3:$C$158,2,0) -> 90 | D24: =VLOOKUP(B24,'rate sheet working'!$B$3:$D$158,3,0) -> 27 | E24: =D24+E25 -> 11879.671 | F24: =VLOOKUP(B24,'rate sheet working'!$B$3:$E$158,4,0) -> 1.9177182 | G24: =VLOOKUP(B24,'rate sheet periphery 1'!$B$5:$F$110,5,0) -> 3.98201 | H24: =F24+G24 -> 5.8997282
A25: 23 | B25: Khargone | C25: =VLOOKUP(B25,'rate sheet working'!$B$3:$C$158,2,0) -> 1320 | D25: =VLOOKUP(B25,'rate sheet working'!$B$3:$D$158,3,0) -> 660 | E25: =D25+E26 -> 11852.671 | F25: =VLOOKUP(B25,'rate sheet working'!$B$3:$E$158,4,0) -> 2.0731461 | G25: =VLOOKUP(B25,'rate sheet periphery 1'!$B$5:$F$110,5,0) -> 3.5897484 | H25: =F25+G25 -> 5.6628945
A26: 24 | B26: Unchahar II (NR) | C26: =VLOOKUP(B26,'rate sheet working'!$B$3:$C$158,2,0) -> 420 | D26: =VLOOKUP(B26,'rate sheet working'!$B$3:$D$158,3,0) -> 1.008 | E26: =D26+E27 -> 11192.671 | F26: =VLOOKUP(B26,'rate sheet working'!$B$3:$E$158,4,0) -> 1.1206832 | G26: =VLOOKUP(B26,'rate sheet periphery 1'!$B$5:$F$110,5,0) -> 4.4444968 | H26: =F26+G26 -> 5.56518
A27: 25 | B27: JP Bina | C27: =VLOOKUP(B27,'rate sheet working'!$B$3:$C$158,2,0) -> 500 | D27: =VLOOKUP(B27,'rate sheet working'!$B$3:$D$158,3,0) -> 350 | E27: =D27+E28 -> 11191.663 | F27: =VLOOKUP(B27,'rate sheet working'!$B$3:$E$158,4,0) -> 1.9099997 | G27: =VLOOKUP(B27,'rate sheet periphery 1'!$B$5:$F$110,5,0) -> 3.59077 | H27: =F27+G27 -> 5.5007697
A28: 26 | B28: RKM Powergen (Talcher Field) (Medium Term) | C28: =VLOOKUP(B28,'rate sheet working'!$B$3:$C$158,2,0) -> 720 | D28: =VLOOKUP(B28,'rate sheet working'!$B$3:$D$158,3,0) -> 72.73 | E28: =D28+E29 -> 10841.663 | F28: =VLOOKUP(B28,'rate sheet working'!$B$3:$E$158,4,0) -> 2.761 | G28: =VLOOKUP(B28,'rate sheet periphery 1'!$B$5:$F$110,5,0) -> 2.6883239 | H28: =F28+G28 -> 5.4493239
A29: 27 | B29: Jindal Power Limited (Medium Term) | C29: =VLOOKUP(B29,'rate sheet working'!$B$3:$C$158,2,0) -> 2400 | D29: =VLOOKUP(B29,'rate sheet working'!$B$3:$D$158,3,0) -> 72.73 | E29: =D29+E30 -> 10768.933 | F29: =VLOOKUP(B29,'rate sheet working'!$B$3:$E$158,4,0) -> 2.6 | G29: =VLOOKUP(B29,'rate sheet periphery 1'!$B$5:$F$110,5,0) -> 2.7850262 | H29: =F29+G29 -> 5.3850262 | I29: =H29-H27 -> -0.11574357
A30: 28 | B30: RKM Powergen (IB Field) (Medium Term) | C30: =VLOOKUP(B30,'rate sheet working'!$B$3:$C$158,2,0) -> 720 | D30: =VLOOKUP(B30,'rate sheet working'!$B$3:$D$158,3,0) -> 72.73 | E30: =D30+E31 -> 10696.203 | F30: =VLOOKUP(B30,'rate sheet working'!$B$3:$E$158,4,0) -> 2.715 | G30: =VLOOKUP(B30,'rate sheet periphery 1'!$B$5:$F$110,5,0) -> 2.6412429 | H30: =F30+G30 -> 5.3562429
A31: 29 | B31: Meja (NR) | C31: =VLOOKUP(B31,'rate sheet working'!$B$3:$C$158,2,0) -> 1320 | D31: =VLOOKUP(B31,'rate sheet working'!$B$3:$D$158,3,0) -> 1.584 | E31: =D31+E32 -> 10623.473 | F31: =VLOOKUP(B31,'rate sheet working'!$B$3:$E$158,4,0) -> 2.2494753 | G31: =VLOOKUP(B31,'rate sheet periphery 1'!$B$5:$F$110,5,0) -> 3.0937435 | H31: =F31+G31 -> 5.3432187
A32: 30 | B32: TRN Energy Pvt. Ltd. (Medium Term) | C32: =VLOOKUP(B32,'rate sheet working'!$B$3:$C$158,2,0) -> 600 | D32: =VLOOKUP(B32,'rate sheet working'!$B$3:$D$158,3,0) -> 24.24 | E32: =D32+E33 -> 10621.889 | F32: =VLOOKUP(B32,'rate sheet working'!$B$3:$E$158,4,0) -> 2.16 | G32: =VLOOKUP(B32,'rate sheet periphery 1'!$B$5:$F$110,5,0) -> 3.0498012 | H32: =F32+G32 -> 5.2098012
A33: 31 | B33: Unchahar IV (NR) | C33: =VLOOKUP(B33,'rate sheet working'!$B$3:$C$158,2,0) -> 500 | D33: =VLOOKUP(B33,'rate sheet working'!$B$3:$D$158,3,0) -> 1.2 | E33: =D33+E34 -> 10597.649 | F33: =VLOOKUP(B33,'rate sheet working'!$B$3:$E$158,4,0) -> 1.6577601 | G33: =VLOOKUP(B33,'rate sheet periphery 1'!$B$5:$F$110,5,0) -> 3.5510387 | H33: =F33+G33 -> 5.2087988
A34: 32 | B34: SKS Power Generation (Medium Term) | C34: =VLOOKUP(B34,'rate sheet working'!$B$3:$C$158,2,0) -> 600 | D34: =VLOOKUP(B34,'rate sheet working'!$B$3:$D$158,3,0) -> 24.24 | E34: =D34+E35 -> 10596.449 | F34: =VLOOKUP(B34,'rate sheet working'!$B$3:$E$158,4,0) -> 2.253 | G34: =VLOOKUP(B34,'rate sheet periphery 1'!$B$5:$F$110,5,0) -> 2.8834484 | H34: =F34+G34 -> 5.1364484
A35: 33 | B35: Jindal India Thermal Power (Medium Term) | C35: =VLOOKUP(B35,'rate sheet working'!$B$3:$C$158,2,0) -> 1200 | D35: =VLOOKUP(B35,'rate sheet working'!$B$3:$D$158,3,0) -> 48.48 | E35: =D35+E36 -> 10572.209 | F35: =VLOOKUP(B35,'rate sheet working'!$B$3:$E$158,4,0) -> 2.57 | G35: =VLOOKUP(B35,'rate sheet periphery 1'!$B$5:$F$110,5,0) -> 2.5476041 | H35: =F35+G35 -> 5.1176041
A36: 34 | B36: Tanda II | C36: =VLOOKUP(B36,'rate sheet working'!$B$3:$C$158,2,0) -> 1320 | D36: =VLOOKUP(B36,'rate sheet working'!$B$3:$D$158,3,0) -> 2.112 | E36: =D36+E37 -> 10523.729 | F36: =VLOOKUP(B36,'rate sheet working'!$B$3:$E$158,4,0) -> 1.7669774 | G36: =VLOOKUP(B36,'rate sheet periphery 1'!$B$5:$F$110,5,0) -> 3.345345 | H36: =F36+G36 -> 5.1123224
A37: 35 | B37: Mauda-I | C37: =VLOOKUP(B37,'rate sheet working'!$B$3:$C$158,2,0) -> 1000 | D37: =VLOOKUP(B37,'rate sheet working'!$B$3:$D$158,3,0) -> 169.12 | E37: =D37+E38 -> 10521.617 | F37: =VLOOKUP(B37,'rate sheet working'!$B$3:$E$158,4,0) -> 1.6931572 | G37: =VLOOKUP(B37,'rate sheet periphery 1'!$B$5:$F$110,5,0) -> 3.3375183 | H37: =F37+G37 -> 5.0306755 | I37: =H37-H28 -> -0.41864837
A38: 36 | B38: MB Power | C38: =VLOOKUP(B38,'rate sheet working'!$B$3:$C$158,2,0) -> 1200 | D38: =VLOOKUP(B38,'rate sheet working'!$B$3:$D$158,3,0) -> 420 | E38: =D38+E39 -> 10352.497 | F38: =VLOOKUP(B38,'rate sheet working'!$B$3:$E$158,4,0) -> 1.6776554 | G38: =VLOOKUP(B38,'rate sheet periphery 1'!$B$5:$F$110,5,0) -> 3.327091 | H38: =F38+G38 -> 5.0047464
A39: 37 | B39: DVC (DTPS) (STOA LOI) | C39: =VLOOKUP(B39,'rate sheet working'!$B$3:$C$158,2,0) -> 1000 | D39: =VLOOKUP(B39,'rate sheet working'!$B$3:$D$158,3,0) -> 100 | E39: =D39+E40 -> 9932.4973 | F39: =VLOOKUP(B39,'rate sheet working'!$B$3:$E$158,4,0) -> 1.5060402 | G39: =VLOOKUP(B39,'rate sheet periphery 1'!$B$5:$F$110,5,0) -> 3.4702929 | H39: =F39+G39 -> 4.9763332
A40: 38 | B40: Mauda-II | C40: =VLOOKUP(B40,'rate sheet working'!$B$3:$C$158,2,0) -> 1320 | D40: =VLOOKUP(B40,'rate sheet working'!$B$3:$D$158,3,0) -> 235.04 | E40: =D40+E41 -> 9832.4973 | F40: =VLOOKUP(B40,'rate sheet working'!$B$3:$E$158,4,0) -> 1.5812064 | G40: =VLOOKUP(B40,'rate sheet periphery 1'!$B$5:$F$110,5,0) -> 3.3322471 | H40: =F40+G40 -> 4.9134535 | I40: =H40-H39 -> -0.062879657
...

Sheet rate sheet periphery 1
G2: 10.04.2026
A3: ='Excl URS 3 '!A1:N1 -> Details of power purchase cost per unit of Thermal and Gas Power stations for MOD for the month of March 2026
A4: Sr. No. | B4: Name of Generating Stations | C4: Installed Capacity (MW) | D4: MPPMCL Share (MW) | E4: Cumulative capacity (MW) | F4: Variable rate at MP periphery in Rs./kwh (excl biomass) | G4: Remarks
A5: 1 | B5: Indira Gandhi STPS (Jhajjar) (NR) | C5: =VLOOKUP(B5,'rate sheet working'!$B$3:$C$158,2,0) -> 1500 | D5: =VLOOKUP(B5,'rate sheet working'!$B$3:$D$158,3,0) -> 1.8 | E5: =D5+E6 -> 12978.414 | F5: =VLOOKUP(B5,'Excl URS 3 '!$B$6:$N$61,13,FALSE) -> 4.447716 | G5: Above 8000 MW partially scheduled
A6: =A5+1 -> 2 | B6: Unchahar II (NR) | C6: =VLOOKUP(B6,'rate sheet working'!$B$3:$C$158,2,0) -> 420 | D6: =VLOOKUP(B6,'rate sheet working'!$B$3:$D$158,3,0) -> 1.008 | E6: =D6+E7 -> 12976.614 | F6: =VLOOKUP(B6,'Excl URS 3 '!$B$6:$N$61,13,FALSE) -> 4.4444968
A7: =A6+1 -> 3 | B7: Solapur I | C7: =VLOOKUP(B7,'rate sheet working'!$B$3:$C$158,2,0) -> 1320 | D7: =VLOOKUP(B7,'rate sheet working'!$B$3:$D$158,3,0) -> 295.88 | E7: =D7+E8 -> 12975.606 | F7: =VLOOKUP(B7,'Excl URS 3 '!$B$6:$N$61,13,FALSE) -> 4.2412187
A8: =A7+1 -> 4 | B8: Gadarwara | C8: =VLOOKUP(B8,'rate sheet working'!$B$3:$C$158,2,0) -> 1600 | D8: =VLOOKUP(B8,'rate sheet working'!$B$3:$D$158,3,0) -> 800 | E8: =D8+E9 -> 12679.726 | F8: =VLOOKUP(B8,'Excl URS 3 '!$B$6:$N$61,13,FALSE) -> 4.1557098
A9: =A8+1 -> 5 | B9: National Capital Thermal Power Station Dadri II (NR) | C9: =VLOOKUP(B9,'rate sheet working'!$B$3:$C$158,2,0) -> 980 | D9: =VLOOKUP(B9,'rate sheet working'!$B$3:$D$158,3,0) -> 2.058 | E9: =D9+E10 -> 11879.726 | F9: =VLOOKUP(B9,'Excl URS 3 '!$B$6:$N$61,13,FALSE) -> 4.1246579
A10: =A9+1 -> 6 | B10: BLA | C10: =VLOOKUP(B10,'rate sheet working'!$B$3:$C$158,2,0) -> 90 | D10: =VLOOKUP(B10,'rate sheet working'!$B$3:$D$158,3,0) -> 27 | E10: =D10+E11 -> 11877.668 | F10: =VLOOKUP(B10,'Excl URS 3 '!$B$6:$N$61,13,FALSE) -> 3.98201
A11: =A10+1 -> 7 | B11: Unchahar I (NR) | C11: =VLOOKUP(B11,'rate sheet working'!$B$3:$C$158,2,0) -> 420 | D11: =VLOOKUP(B11,'rate sheet working'!$B$3:$D$158,3,0) -> 0.336 | E11: =D11+E12 -> 11850.668 | F11: =VLOOKUP(B11,'Excl URS 3 '!$B$6:$N$61,13,FALSE) -> 3.6992354
A12: =A11+1 -> 8 | B12: Unchahar III (NR) | C12: =VLOOKUP(B12,'rate sheet working'!$B$3:$C$158,2,0) -> 210 | D12: =VLOOKUP(B12,'rate sheet working'!$B$3:$D$158,3,0) -> 0.483 | E12: =D12+E13 -> 11850.332 | F12: =VLOOKUP(B12,'Excl URS 3 '!$B$6:$N$61,13,FALSE) -> 3.6889117
A13: =A12+1 -> 9 | B13: JP Bina | C13: =VLOOKUP(B13,'rate sheet working'!$B$3:$C$158,2,0) -> 500 | D13: =VLOOKUP(B13,'rate sheet working'!$B$3:$D$158,3,0) -> 350 | E13: =D13+E14 -> 11849.849 | F13: =VLOOKUP(B13,'Excl URS 3 '!$B$6:$N$61,13,FALSE) -> 3.59077
A14: =A13+1 -> 10 | B14: Khargone | C14: =VLOOKUP(B14,'rate sheet working'!$B$3:$C$158,2,0) -> 1320 | D14: =VLOOKUP(B14,'rate sheet working'!$B$3:$D$158,3,0) -> 660 | E14: =D14+E15 -> 11499.849 | F14: =VLOOKUP(B14,'Excl URS 3 '!$B$6:$N$61,13,FALSE) -> 3.5897484
A15: =A14+1 -> 11 | B15: Ghatampur Thermal Power Station (NUPPL) | C15: =VLOOKUP(B15,'rate sheet working'!$B$3:$C$158,2,0) -> 660 | D15: =VLOOKUP(B15,'rate sheet working'!$B$3:$D$158,3,0) -> 1.0626 | E15: =D15+E16 -> 10839.849 | F15: =VLOOKUP(B15,'Excl URS 3 '!$B$6:$N$61,13,FALSE) -> 3.5697845
A16: =A15+1 -> 12 | B16: Unchahar IV (NR) | C16: =VLOOKUP(B16,'rate sheet working'!$B$3:$C$158,2,0) -> 500 | D16: =VLOOKUP(B16,'rate sheet working'!$B$3:$D$158,3,0) -> 1.2 | E16: =D16+E17 -> 10838.786 | F16: =VLOOKUP(B16,'Excl URS 3 '!$B$6:$N$61,13,FALSE) -> 3.5510387
A17: =A16+1 -> 13 | B17: DVC (DTPS) (STOA LOI) | C17: =VLOOKUP(B17,'rate sheet working'!$B$3:$C$158,2,0) -> 1000 | D17: =VLOOKUP(B17,'rate sheet working'!$B$3:$D$158,3,0) -> 100 | E17: =D17+E18 -> 10837.586 | F17: =VLOOKUP(B17,'Excl URS 3 '!$B$6:$N$61,13,FALSE) -> 3.4702929
... A24: =A23+1 -> 20 | B24: SGTPS -4x210 | C24: =VLOOKUP(B24,'rate sheet working'!$B$3:$C$158,2,0) -> 840 | D24: =VLOOKUP(B24,'rate sheet working'!$B$3:$D$158,3,0) -> 840 | E24: =D24+E25 -> 8709.7303 | F24: =VLOOKUP(B24,'Excl URS 3 '!$B$6:$N$61,13,FALSE) -> 3.067
